Workbook

Sheet Operaciones
A1: ID | B1: Fecha apertura | C1: Activo | D1: Estrategia | E1: Strike venta | F1: Strike compra | G1: Vencimiento | H1: Contratos | I1: Multiplicador | J1: Precio subyacente apertura | K1: Prima apertura (por acción) | L1: Comisiones apertura $ | M1: Estado | N1: Fecha cierre | O1: Prima cierre (por acción) | P1: Comisiones cierre $ | Q1: Capital en riesgo manual $ | R1: ID lote acciones | S1: Notas | T1: Familia | U1: Crédito / Débito | V1: Método capital | W1: DTE apertura | X1: Días en operación | Y1: DTE restantes | Z1: Prima neta $ | AA1: Strike principal | AB1: Break-even | AC1: Colchón OTM % (apertura) | AD1: Capital en riesgo $ | AE1: Resultado prima $ | AF1: Rentabilidad s/ capital % | AG1: ARORC realizado % | AH1: ROC máximo % | AI1: ARORC esperado % | AJ1: % prima capturada | AK1: Mes cierre | AL1: Finalizada (1/0) | AM1: Capital × días | AN1: Control
A2: 1 | B2: 46266 | C2: SOFI | D2: Put vendida (CSP) | E2: 15 | G2: 46291 | H2: 2 | I2: 100 | J2: 16.4 | K2: 0.42 | L2: 2.1 | M2: Vencida | N2: 46291 | P2: 0 | S2: EJEMPLO · borrar esta fila | T2: =IF($C2="","",IFERROR(INDEX(Listas!$B$2:$B$20,MATCH($D2,Listas!$A$2:$A$20,0)),"")) -> Put | U2: =IF($C2="","",IFERROR(INDEX(Listas!$C$2:$C$20,MATCH($D2,Listas!$A$2:$A$20,0)),"")) -> Crédito | V2: =IF($C2="","",IFERROR(INDEX(Listas!$D$2:$D$20,MATCH($D2,Listas!$A$2:$A$20,0)),"")) -> Strike | W2: =IF(OR($C2="",$B2="",$G2=""),"",$G2-$B2) -> 25 | X2: =IF(OR($C2="",$B2=""),"",IF($N2<>"",$N2,TODAY())-$B2) -> 25 | Y2: =IF(OR($C2="",$M2<>"Abierta",$G2=""),"",MAX($G2-TODAY(),0)) | Z2: =IF($C2="","",N($K2)*N($H2)*N($I2)*IF($U2="Débito",-1,1)) -> 84 | AA2: =IF($C2="","",IF(AND($U2="Débito",$F2<>""),$F2,$E2)) -> 15 | AB2: =IF(OR($C2="",$T2="Mixta",$AA2=""),"",IF($V2="Subyacente",IF($J2="","",$J2-$K2),IF($T2="Put",$AA2-$K2,$AA2+$K2))) -> 14.58 | AC2: =IF(OR($C2="",$T2="Mixta",$J2="",$AA2=""),"",IF($T2="Put",($J2-$AA2)/$J2,($AA2-$J2)/$J2)) -> 0.085365854 | AD2: =IF($C2="","",IF($Q2<>"",$Q2,IF($V2="Strike",N($E2)*$H2*$I2,IF($V2="Subyacente",IF($J2="","",$J2*$H2*$I2),IF($V2="Ancho",IF($F2="","",ABS($E2-$F2)*$H2*$I2-$K2*$H2*$I2),IF($V2="Prima",$K2*$H2*$I2,"")))))) -> 3000 | AE2: =IF(OR($C2="",$M2="Abierta",$M2=""),"",(N($K2)-IF(OR($M2="Cerrada",$M2="Rolada"),N($O2),0))*$H2*$I2*IF($U2="Débito",-1,1)-N($L2)-N($P2)) -> 81.9 | AF2: =IF(OR($AE2="",$AD2=""),"",IF($AD2<=0,"",$AE2/$AD2)) -> 0.0273 | AG2: =IF($AF2="","",$AF2*365/MAX(N($X2),1)) -> 0.39858 | AH2: =IF(OR($C2="",$U2<>"Crédito",$AD2=""),"",IF($AD2<=0,"",($Z2-N($L2))/$AD2)) -> 0.0273 | AI2: =IF(OR($AH2="",$W2=""),"",$AH2*365/MAX($W2,1)) -> 0.39858 | AJ2: =IF(OR($AE2="",$U2<>"Crédito",N($K2)=0),"",(N($K2)-IF(OR($M2="Cerrada",$M2="Rolada"),N($O2),0))/$K2) -> 1 | AK2: =IF(OR($C2="",$N2=""),"",DATE(YEAR($N2),MONTH($N2),1)) -> 46266 | AL2: =IF($C2="","",IF($M2="Abierta",0,1)) -> 1 | AM2: =IF(OR($AE2="",$AD2=""),"",$AD2*MAX(N($X2),1)) -> 75000 | AN2: =IF($C2="","",IF(OR($B2="",$D2="",$H2="",$K2="",$M2=""),"Faltan datos obligatorios",IF($T2="","Estrategia no reconocida",IF(AND($M2<>"Abierta",$N2=""),"Falta fecha cierre",IF(AND(OR($M2="Cerrada",$M2="Rolada"),$O2=""),"Falta prima cierre",IF(AND($N2<>"",$N2<$B2),"Cierre anterior a apertura",IF(AND($M2="Asignada",$R2=""),"Asignada: falta ID lote acciones",IF(AND($R2<>"",ISNA(MATCH($R2,Acciones!$A$2:$A$201,0))),"El ID lote no existe en Acciones",IF($AD2="","Revisa capital en riesgo","OK"))))))))) -> OK
A3: 2 | B3: 46273 | C3: AMD | D3: Put Credit Spread | E3: 140 | F3: 135 | G3: 46312 | H3: 1 | I3: 100 | J3: 152.3 | K3: 1.15 | L3: 1.4 | M3: Cerrada | N3: 46296 | O3: 0.35 | P3: 1.4 | S3: EJEMPLO · borrar esta fila | T3: =IF($C3="","",IFERROR(INDEX(Listas!$B$2:$B$20,MATCH($D3,Listas!$A$2:$A$20,0)),"")) -> Put | U3: =IF($C3="","",IFERROR(INDEX(Listas!$C$2:$C$20,MATCH($D3,Listas!$A$2:$A$20,0)),"")) -> Crédito | V3: =IF($C3="","",IFERROR(INDEX(Listas!$D$2:$D$20,MATCH($D3,Listas!$A$2:$A$20,0)),"")) -> Ancho | W3: =IF(OR($C3="",$B3="",$G3=""),"",$G3-$B3) -> 39 | X3: =IF(OR($C3="",$B3=""),"",IF($N3<>"",$N3,TODAY())-$B3) -> 23 | Y3: =IF(OR($C3="",$M3<>"Abierta",$G3=""),"",MAX($G3-TODAY(),0)) | Z3: =IF($C3="","",N($K3)*N($H3)*N($I3)*IF($U3="Débito",-1,1)) -> 115 | AA3: =IF($C3="","",IF(AND($U3="Débito",$F3<>""),$F3,$E3)) -> 140 | AB3: =IF(OR($C3="",$T3="Mixta",$AA3=""),"",IF($V3="Subyacente",IF($J3="","",$J3-$K3),IF($T3="Put",$AA3-$K3,$AA3+$K3))) -> 138.85 | AC3: =IF(OR($C3="",$T3="Mixta",$J3="",$AA3=""),"",IF($T3="Put",($J3-$AA3)/$J3,($AA3-$J3)/$J3)) -> 0.080761655 | AD3: =IF($C3="","",IF($Q3<>"",$Q3,IF($V3="Strike",N($E3)*$H3*$I3,IF($V3="Subyacente",IF($J3="","",$J3*$H3*$I3),IF($V3="Ancho",IF($F3="","",ABS($E3-$F3)*$H3*$I3-$K3*$H3*$I3),IF($V3="Prima",$K3*$H3*$I3,"")))))) -> 385 | AE3: =IF(OR($C3="",$M3="Abierta",$M3=""),"",(N($K3)-IF(OR($M3="Cerrada",$M3="Rolada"),N($O3),0))*$H3*$I3*IF($U3="Débito",-1,1)-N($L3)-N($P3)) -> 77.2 | AF3: =IF(OR($AE3="",$AD3=""),"",IF($AD3<=0,"",$AE3/$AD3)) -> 0.20051948 | AG3: =IF($AF3="","",$AF3*365/MAX(N($X3),1)) -> 3.182157 | AH3: =IF(OR($C3="",$U3<>"Crédito",$AD3=""),"",IF($AD3<=0,"",($Z3-N($L3))/$AD3)) -> 0.29506494 | AI3: =IF(OR($AH3="",$W3=""),"",$AH3*365/MAX($W3,1)) -> 2.7615052 | AJ3: =IF(OR($AE3="",$U3<>"Crédito",N($K3)=0),"",(N($K3)-IF(OR($M3="Cerrada",$M3="Rolada"),N($O3),0))/$K3) -> 0.69565217 | AK3: =IF(OR($C3="",$N3=""),"",DATE(YEAR($N3),MONTH($N3),1)) -> 46296 | AL3: =IF($C3="","",IF($M3="Abierta",0,1)) -> 1 | AM3: =IF(OR($AE3="",$AD3=""),"",$AD3*MAX(N($X3),1)) -> 8855 | AN3: =IF($C3="","",IF(OR($B3="",$D3="",$H3="",$K3="",$M3=""),"Faltan datos obligatorios",IF($T3="","Estrategia no reconocida",IF(AND($M3<>"Abierta",$N3=""),"Falta fecha cierre",IF(AND(OR($M3="Cerrada",$M3="Rolada"),$O3=""),"Falta prima cierre",IF(AND($N3<>"",$N3<$B3),"Cierre anterior a apertura",IF(AND($M3="Asignada",$R3=""),"Asignada: falta ID lote acciones",IF(AND($R3<>"",ISNA(MATCH($R3,Acciones!$A$2:$A$201,0))),"El ID lote no existe en Acciones",IF($AD3="","Revisa capital en riesgo","OK"))))))))) -> OK
A4: 3 | B4: 46296 | C4: INTC | D4: Put vendida (CSP) | E4: 22 | G4: 46325 | H4: 2 | I4: 100 | J4: 23.8 | K4: 0.55 | L4: 2.1 | M4: Abierta | S4: EJEMPLO · borrar esta fila | T4: =IF($C4="","",IFERROR(INDEX(Listas!$B$2:$B$20,MATCH($D4,Listas!$A$2:$A$20,0)),"")) -> Put | U4: =IF($C4="","",IFERROR(INDEX(Listas!$C$2:$C$20,MATCH($D4,Listas!$A$2:$A$20,0)),"")) -> Crédito | V4: =IF($C4="","",IFERROR(INDEX(Listas!$D$2:$D$20,MATCH($D4,Listas!$A$2:$A$20,0)),"")) -> Strike | W4: =IF(OR($C4="",$B4="",$G4=""),"",$G4-$B4) -> 29 | X4: =IF(OR($C4="",$B4=""),"",IF($N4<>"",$N4,TODAY())-$B4) -> 12 | Y4: =IF(OR($C4="",$M4<>"Abierta",$G4=""),"",MAX($G4-TODAY(),0)) -> 17 | Z4: =IF($C4="","",N($K4)*N($H4)*N($I4)*IF($U4="Débito",-1,1)) -> 110 | AA4: =IF($C4="","",IF(AND($U4="Débito",$F4<>""),$F4,$E4)) -> 22 | AB4: =IF(OR($C4="",$T4="Mixta",$AA4=""),"",IF($V4="Subyacente",IF($J4="","",$J4-$K4),IF($T4="Put",$AA4-$K4,$AA4+$K4))) -> 21.45 | AC4: =IF(OR($C4="",$T4="Mixta",$J4="",$AA4=""),"",IF($T4="Put",($J4-$AA4)/$J4,($AA4-$J4)/$J4)) -> 0.075630252 | AD4: =IF($C4="","",IF($Q4<>"",$Q4,IF($V4="Strike",N($E4)*$H4*$I4,IF($V4="Subyacente",IF($J4="","",$J4*$H4*$I4),IF($V4="Ancho",IF($F4="","",ABS($E4-$F4)*$H4*$I4-$K4*$H4*$I4),IF($V4="Prima",$K4*$H4*$I4,"")))))) -> 4400 | AE4: =IF(OR($C4="",$M4="Abierta",$M4=""),"",(N($K4)-IF(OR($M4="Cerrada",$M4="Rolada"),N($O4),0))*$H4*$I4*IF($U4="Débito",-1,1)-N($L4)-N($P4)) | AF4: =IF(OR($AE4="",$AD4=""),"",IF($AD4<=0,"",$AE4/$AD4)) | AG4: =IF($AF4="","",$AF4*365/MAX(N($X4),1)) | AH4: =IF(OR($C4="",$U4<>"Crédito",$AD4=""),"",IF($AD4<=0,"",($Z4-N($L4))/$AD4)) -> 0.024522727 | AI4: =IF(OR($AH4="",$W4=""),"",$AH4*365/MAX($W4,1)) -> 0.30864812 | AJ4: =IF(OR($AE4="",$U4<>"Crédito",N($K4)=0),"",(N($K4)-IF(OR($M4="Cerrada",$M4="Rolada"),N($O4),0))/$K4) | AK4: =IF(OR($C4="",$N4=""),"",DATE(YEAR($N4),MONTH($N4),1)) | AL4: =IF($C4="","",IF($M4="Abierta",0,1)) -> 0 | AM4: =IF(OR($AE4="",$AD4=""),"",$AD4*MAX(N($X4),1)) | AN4: =IF($C4="","",IF(OR($B4="",$D4="",$H4="",$K4="",$M4=""),"Faltan datos obligatorios",IF($T4="","Estrategia no reconocida",IF(AND($M4<>"Abierta",$N4=""),"Falta fecha cierre",IF(AND(OR($M4="Cerrada",$M4="Rolada"),$O4=""),"Falta prima cierre",IF(AND($N4<>"",$N4<$B4),"Cierre anterior a apertura",IF(AND($M4="Asignada",$R4=""),"Asignada: falta ID lote acciones",IF(AND($R4<>"",ISNA(MATCH($R4,Acciones!$A$2:$A$201,0))),"El ID lote no existe en Acciones",IF($AD4="","Revisa capital en riesgo","OK"))))))))) -> OK
A5: 4 | B5: 46259 | C5: KO | D5: Put vendida (CSP) | E5: 65 | G5: 46283 | H5: 1 | I5: 100 | J5: 66.1 | K5: 0.8 | L5: 1.05 | M5: Asignada | N5: 46283 | R5: L1 | S5: EJEMPLO · borrar esta fila · put asignada → lote L1 | T5: =IF($C5="","",IFERROR(INDEX(Listas!$B$2:$B$20,MATCH($D5,Listas!$A$2:$A$20,0)),"")) -> Put | U5: =IF($C5="","",IFERROR(INDEX(Listas!$C$2:$C$20,MATCH($D5,Listas!$A$2:$A$20,0)),"")) -> Crédito | V5: =IF($C5="","",IFERROR(INDEX(Listas!$D$2:$D$20,MATCH($D5,Listas!$A$2:$A$20,0)),"")) -> Strike | W5: =IF(OR($C5="",$B5="",$G5=""),"",$G5-$B5) -> 24 | X5: =IF(OR($C5="",$B5=""),"",IF($N5<>"",$N5,TODAY())-$B5) -> 24 | Y5: =IF(OR($C5="",$M5<>"Abierta",$G5=""),"",MAX($G5-TODAY(),0)) | Z5: =IF($C5="","",N($K5)*N($H5)*N($I5)*IF($U5="Débito",-1,1)) -> 80 | AA5: =IF($C5="","",IF(AND($U5="Débito",$F5<>""),$F5,$E5)) -> 65 | AB5: =IF(OR($C5="",$T5="Mixta",$AA5=""),"",IF($V5="Subyacente",IF($J5="","",$J5-$K5),IF($T5="Put",$AA5-$K5,$AA5+$K5))) -> 64.2 | AC5: =IF(OR($C5="",$T5="Mixta",$J5="",$AA5=""),"",IF($T5="Put",($J5-$AA5)/$J5,($AA5-$J5)/$J5)) -> 0.016641452 | AD5: =IF($C5="","",IF($Q5<>"",$Q5,IF($V5="Strike",N($E5)*$H5*$I5,IF($V5="Subyacente",IF($J5="","",$J5*$H5*$I5),IF($V5="Ancho",IF($F5="","",ABS($E5-$F5)*$H5*$I5-$K5*$H5*$I5),IF($V5="Prima",$K5*$H5*$I5,"")))))) -> 6500 | AE5: =IF(OR($C5="",$M5="Abierta",$M5=""),"",(N($K5)-IF(OR($M5="Cerrada",$M5="Rolada"),N($O5),0))*$H5*$I5*IF($U5="Débito",-1,1)-N($L5)-N($P5)) -> 78.95 | AF5: =IF(OR($AE5="",$AD5=""),"",IF($AD5<=0,"",$AE5/$AD5)) -> 0.012146154 | AG5: =IF($AF5="","",$AF5*365/MAX(N($X5),1)) -> 0.18472276 | AH5: =IF(OR($C5="",$U5<>"Crédito",$AD5=""),"",IF($AD5<=0,"",($Z5-N($L5))/$AD5)) -> 0.012146154 | AI5: =IF(OR($AH5="",$W5=""),"",$AH5*365/MAX($W5,1)) -> 0.18472276 | AJ5: =IF(OR($AE5="",$U5<>"Crédito",N($K5)=0),"",(N($K5)-IF(OR($M5="Cerrada",$M5="Rolada"),N($O5),0))/$K5) -> 1 | AK5: =IF(OR($C5="",$N5=""),"",DATE(YEAR($N5),MONTH($N5),1)) -> 46266 | AL5: =IF($C5="","",IF($M5="Abierta",0,1)) -> 1 | AM5: =IF(OR($AE5="",$AD5=""),"",$AD5*MAX(N($X5),1)) -> 156000 | AN5: =IF($C5="","",IF(OR($B5="",$D5="",$H5="",$K5="",$M5=""),"Faltan datos obligatorios",IF($T5="","Estrategia no reconocida",IF(AND($M5<>"Abierta",$N5=""),"Falta fecha cierre",IF(AND(OR($M5="Cerrada",$M5="Rolada"),$O5=""),"Falta prima cierre",IF(AND($N5<>"",$N5<$B5),"Cierre anterior a apertura",IF(AND($M5="Asignada",$R5=""),"Asignada: falta ID lote acciones",IF(AND($R5<>"",ISNA(MATCH($R5,Acciones!$A$2:$A$201,0))),"El ID lote no existe en Acciones",IF($AD5="","Revisa capital en riesgo","OK"))))))))) -> OK
A6: 5 | B6: 46287 | C6: KO | D6: Call cubierta (CC) | E6: 68 | G6: 46312 | H6: 1 | I6: 100 | J6: 65.4 | K6: 0.45 | L6: 1.05 | M6: Abierta | R6: L1 | S6: EJEMPLO · borrar esta fila · call sobre el lote L1 | T6: =IF($C6="","",IFERROR(INDEX(Listas!$B$2:$B$20,MATCH($D6,Listas!$A$2:$A$20,0)),"")) -> Call | U6: =IF($C6="","",IFERROR(INDEX(Listas!$C$2:$C$20,MATCH($D6,Listas!$A$2:$A$20,0)),"")) -> Crédito | V6: =IF($C6="","",IFERROR(INDEX(Listas!$D$2:$D$20,MATCH($D6,Listas!$A$2:$A$20,0)),"")) -> Subyacente | W6: =IF(OR($C6="",$B6="",$G6=""),"",$G6-$B6) -> 25 | X6: =IF(OR($C6="",$B6=""),"",IF($N6<>"",$N6,TODAY())-$B6) -> 21 | Y6: =IF(OR($C6="",$M6<>"Abierta",$G6=""),"",MAX($G6-TODAY(),0)) -> 4 | Z6: =IF($C6="","",N($K6)*N($H6)*N($I6)*IF($U6="Débito",-1,1)) -> 45 | AA6: =IF($C6="","",IF(AND($U6="Débito",$F6<>""),$F6,$E6)) -> 68 | AB6: =IF(OR($C6="",$T6="Mixta",$AA6=""),"",IF($V6="Subyacente",IF($J6="","",$J6-$K6),IF($T6="Put",$AA6-$K6,$AA6+$K6))) -> 64.95 | AC6: =IF(OR($C6="",$T6="Mixta",$J6="",$AA6=""),"",IF($T6="Put",($J6-$AA6)/$J6,($AA6-$J6)/$J6)) -> 0.039755352 | AD6: =IF($C6="","",IF($Q6<>"",$Q6,IF($V6="Strike",N($E6)*$H6*$I6,IF($V6="Subyacente",IF($J6="","",$J6*$H6*$I6),IF($V6="Ancho",IF($F6="","",ABS($E6-$F6)*$H6*$I6-$K6*$H6*$I6),IF($V6="Prima",$K6*$H6*$I6,"")))))) -> 6540 | AE6: =IF(OR($C6="",$M6="Abierta",$M6=""),"",(N($K6)-IF(OR($M6="Cerrada",$M6="Rolada"),N($O6),0))*$H6*$I6*IF($U6="Débito",-1,1)-N($L6)-N($P6)) | AF6: =IF(OR($AE6="",$AD6=""),"",IF($AD6<=0,"",$AE6/$AD6)) | AG6: =IF($AF6="","",$AF6*365/MAX(N($X6),1)) | AH6: =IF(OR($C6="",$U6<>"Crédito",$AD6=""),"",IF($AD6<=0,"",($Z6-N($L6))/$AD6)) -> 0.0067201835 | AI6: =IF(OR($AH6="",$W6=""),"",$AH6*365/MAX($W6,1)) -> 0.098114679 | AJ6: =IF(OR($AE6="",$U6<>"Crédito",N($K6)=0),"",(N($K6)-IF(OR($M6="Cerrada",$M6="Rolada"),N($O6),0))/$K6) | AK6: =IF(OR($C6="",$N6=""),"",DATE(YEAR($N6),MONTH($N6),1)) | AL6: =IF($C6="","",IF($M6="Abierta",0,1)) -> 0 | AM6: =IF(OR($AE6="",$AD6=""),"",$AD6*MAX(N($X6),1)) | AN6: =IF($C6="","",IF(OR($B6="",$D6="",$H6="",$K6="",$M6=""),"Faltan datos obligatorios",IF($T6="","Estrategia no reconocida",IF(AND($M6<>"Abierta",$N6=""),"Falta fecha cierre",IF(AND(OR($M6="Cerrada",$M6="Rolada"),$O6=""),"Falta prima cierre",IF(AND($N6<>"",$N6<$B6),"Cierre anterior a apertura",IF(AND($M6="Asignada",$R6=""),"Asignada: falta ID lote acciones",IF(AND($R6<>"",ISNA(MATCH($R6,Acciones!$A$2:$A$201,0))),"El ID lote no existe en Acciones",IF($AD6="","Revisa capital en riesgo","OK"))))))))) -> OK
I7: 100 | T7: =IF($C7="","",IFERROR(INDEX(Listas!$B$2:$B$20,MATCH($D7,Listas!$A$2:$A$20,0)),"")) | U7: =IF($C7="","",IFERROR(INDEX(Listas!$C$2:$C$20,MATCH($D7,Listas!$A$2:$A$20,0)),"")) | V7: =IF($C7="","",IFERROR(INDEX(Listas!$D$2:$D$20,MATCH($D7,Listas!$A$2:$A$20,0)),"")) | W7: =IF(OR($C7="",$B7="",$G7=""),"",$G7-$B7) | X7: =IF(OR($C7="",$B7=""),"",IF($N7<>"",$N7,TODAY())-$B7) | Y7: =IF(OR($C7="",$M7<>"Abierta",$G7=""),"",MAX($G7-TODAY(),0)) | Z7: =IF($C7="","",N($K7)*N($H7)*N($I7)*IF($U7="Débito",-1,1)) | AA7: =IF($C7="","",IF(AND($U7="Débito",$F7<>""),$F7,$E7)) | AB7: =IF(OR($C7="",$T7="Mixta",$AA7=""),"",IF($V7="Subyacente",IF($J7="","",$J7-$K7),IF($T7="Put",$AA7-$K7,$AA7+$K7))) | AC7: =IF(OR($C7="",$T7="Mixta",$J7="",$AA7=""),"",IF($T7="Put",($J7-$AA7)/$J7,($AA7-$J7)/$J7)) | AD7: =IF($C7="","",IF($Q7<>"",$Q7,IF($V7="Strike",N($E7)*$H7*$I7,IF($V7="Subyacente",IF($J7="","",$J7*$H7*$I7),IF($V7="Ancho",IF($F7="","",ABS($E7-$F7)*$H7*$I7-$K7*$H7*$I7),IF($V7="Prima",$K7*$H7*$I7,"")))))) | AE7: =IF(OR($C7="",$M7="Abierta",$M7=""),"",(N($K7)-IF(OR($M7="Cerrada",$M7="Rolada"),N($O7),0))*$H7*$I7*IF($U7="Débito",-1,1)-N($L7)-N($P7)) | AF7: =IF(OR($AE7="",$AD7=""),"",IF($AD7<=0,"",$AE7/$AD7)) | AG7: =IF($AF7="","",$AF7*365/MAX(N($X7),1)) | AH7: =IF(OR($C7="",$U7<>"Crédito",$AD7=""),"",IF($AD7<=0,"",($Z7-N($L7))/$AD7)) | AI7: =IF(OR($AH7="",$W7=""),"",$AH7*365/MAX($W7,1)) | AJ7: =IF(OR($AE7="",$U7<>"Crédito",N($K7)=0),"",(N($K7)-IF(OR($M7="Cerrada",$M7="Rolada"),N($O7),0))/$K7) | AK7: =IF(OR($C7="",$N7=""),"",DATE(YEAR($N7),MONTH($N7),1)) | AL7: =IF($C7="","",IF($M7="Abierta",0,1)) | AM7: =IF(OR($AE7="",$AD7=""),"",$AD7*MAX(N($X7),1)) | AN7: =IF($C7="","",IF(OR($B7="",$D7="",$H7="",$K7="",$M7=""),"Faltan datos obligatorios",IF($T7="","Estrategia no reconocida",IF(AND($M7<>"Abierta",$N7=""),"Falta fecha cierre",IF(AND(OR($M7="Cerrada",$M7="Rolada"),$O7=""),"Falta prima cierre",IF(AND($N7<>"",$N7<$B7),"Cierre anterior a apertura",IF(AND($M7="Asignada",$R7=""),"Asignada: falta ID lote acciones",IF(AND($R7<>"",ISNA(MATCH($R7,Acciones!$A$2:$A$201,0))),"El ID lote no existe en Acciones",IF($AD7="","Revisa capital en riesgo","OK")))))))))
I8: 100 | T8: =IF($C8="","",IFERROR(INDEX(Listas!$B$2:$B$20,MATCH($D8,Listas!$A$2:$A$20,0)),"")) | U8: =IF($C8="","",IFERROR(INDEX(Listas!$C$2:$C$20,MATCH($D8,Listas!$A$2:$A$20,0)),"")) | V8: =IF($C8="","",IFERROR(INDEX(Listas!$D$2:$D$20,MATCH($D8,Listas!$A$2:$A$20,0)),"")) | W8: =IF(OR($C8="",$B8="",$G8=""),"",$G8-$B8) | X8: =IF(OR($C8="",$B8=""),"",IF($N8<>"",$N8,TODAY())-$B8) | Y8: =IF(OR($C8="",$M8<>"Abierta",$G8=""),"",MAX($G8-TODAY(),0)) | Z8: =IF($C8="","",N($K8)*N($H8)*N($I8)*IF($U8="Débito",-1,1)) | AA8: =IF($C8="","",IF(AND($U8="Débito",$F8<>""),$F8,$E8)) | AB8: =IF(OR($C8="",$T8="Mixta",$AA8=""),"",IF($V8="Subyacente",IF($J8="","",$J8-$K8),IF($T8="Put",$AA8-$K8,$AA8+$K8))) | AC8: =IF(OR($C8="",$T8="Mixta",$J8="",$AA8=""),"",IF($T8="Put",($J8-$AA8)/$J8,($AA8-$J8)/$J8)) | AD8: =IF($C8="","",IF($Q8<>"",$Q8,IF($V8="Strike",N($E8)*$H8*$I8,IF($V8="Subyacente",IF($J8="","",$J8*$H8*$I8),IF($V8="Ancho",IF($F8="","",ABS($E8-$F8)*$H8*$I8-$K8*$H8*$I8),IF($V8="Prima",$K8*$H8*$I8,"")))))) | AE8: =IF(OR($C8="",$M8="Abierta",$M8=""),"",(N($K8)-IF(OR($M8="Cerrada",$M8="Rolada"),N($O8),0))*$H8*$I8*IF($U8="Débito",-1,1)-N($L8)-N($P8)) | AF8: =IF(OR($AE8="",$AD8=""),"",IF($AD8<=0,"",$AE8/$AD8)) | AG8: =IF($AF8="","",$AF8*365/MAX(N($X8),1)) | AH8: =IF(OR($C8="",$U8<>"Crédito",$AD8=""),"",IF($AD8<=0,"",($Z8-N($L8))/$AD8)) | AI8: =IF(OR($AH8="",$W8=""),"",$AH8*365/MAX($W8,1)) | AJ8: =IF(OR($AE8="",$U8<>"Crédito",N($K8)=0),"",(N($K8)-IF(OR($M8="Cerrada",$M8="Rolada"),N($O8),0))/$K8) | AK8: =IF(OR($C8="",$N8=""),"",DATE(YEAR($N8),MONTH($N8),1)) | AL8: =IF($C8="","",IF($M8="Abierta",0,1)) | AM8: =IF(OR($AE8="",$AD8=""),"",$AD8*MAX(N($X8),1)) | AN8: =IF($C8="","",IF(OR($B8="",$D8="",$H8="",$K8="",$M8=""),"Faltan datos obligatorios",IF($T8="","Estrategia no reconocida",IF(AND($M8<>"Abierta",$N8=""),"Falta fecha cierre",IF(AND(OR($M8="Cerrada",$M8="Rolada"),$O8=""),"Falta prima cierre",IF(AND($N8<>"",$N8<$B8),"Cierre anterior a apertura",IF(AND($M8="Asignada",$R8=""),"Asignada: falta ID lote acciones",IF(AND($R8<>"",ISNA(MATCH($R8,Acciones!$A$2:$A$201,0))),"El ID lote no existe en Acciones",IF($AD8="","Revisa capital en riesgo","OK")))))))))
I9: 100 | T9: =IF($C9="","",IFERROR(INDEX(Listas!$B$2:$B$20,MATCH($D9,Listas!$A$2:$A$20,0)),"")) | U9: =IF($C9="","",IFERROR(INDEX(Listas!$C$2:$C$20,MATCH($D9,Listas!$A$2:$A$20,0)),"")) | V9: =IF($C9="","",IFERROR(INDEX(Listas!$D$2:$D$20,MATCH($D9,Listas!$A$2:$A$20,0)),"")) | W9: =IF(OR($C9="",$B9="",$G9=""),"",$G9-$B9) | X9: =IF(OR($C9="",$B9=""),"",IF($N9<>"",$N9,TODAY())-$B9) | Y9: =IF(OR($C9="",$M9<>"Abierta",$G9=""),"",MAX($G9-TODAY(),0)) | Z9: =IF($C9="","",N($K9)*N($H9)*N($I9)*IF($U9="Débito",-1,1)) | AA9: =IF($C9="","",IF(AND($U9="Débito",$F9<>""),$F9,$E9)) | AB9: =IF(OR($C9="",$T9="Mixta",$AA9=""),"",IF($V9="Subyacente",IF($J9="","",$J9-$K9),IF($T9="Put",$AA9-$K9,$AA9+$K9))) | AC9: =IF(OR($C9="",$T9="Mixta",$J9="",$AA9=""),"",IF($T9="Put",($J9-$AA9)/$J9,($AA9-$J9)/$J9)) | AD9: =IF($C9="","",IF($Q9<>"",$Q9,IF($V9="Strike",N($E9)*$H9*$I9,IF($V9="Subyacente",IF($J9="","",$J9*$H9*$I9),IF($V9="Ancho",IF($F9="","",ABS($E9-$F9)*$H9*$I9-$K9*$H9*$I9),IF($V9="Prima",$K9*$H9*$I9,"")))))) | AE9: =IF(OR($C9="",$M9="Abierta",$M9=""),"",(N($K9)-IF(OR($M9="Cerrada",$M9="Rolada"),N($O9),0))*$H9*$I9*IF($U9="Débito",-1,1)-N($L9)-N($P9)) | AF9: =IF(OR($AE9="",$AD9=""),"",IF($AD9<=0,"",$AE9/$AD9)) | AG9: =IF($AF9="","",$AF9*365/MAX(N($X9),1)) | AH9: =IF(OR($C9="",$U9<>"Crédito",$AD9=""),"",IF($AD9<=0,"",($Z9-N($L9))/$AD9)) | AI9: =IF(OR($AH9="",$W9=""),"",$AH9*365/MAX($W9,1)) | AJ9: =IF(OR($AE9="",$U9<>"Crédito",N($K9)=0),"",(N($K9)-IF(OR($M9="Cerrada",$M9="Rolada"),N($O9),0))/$K9) | AK9: =IF(OR($C9="",$N9=""),"",DATE(YEAR($N9),MONTH($N9),1)) | AL9: =IF($C9="","",IF($M9="Abierta",0,1)) | AM9: =IF(OR($AE9="",$AD9=""),"",$AD9*MAX(N($X9),1)) | AN9: =IF($C9="","",IF(OR($B9="",$D9="",$H9="",$K9="",$M9=""),"Faltan datos obligatorios",IF($T9="","Estrategia no reconocida",IF(AND($M9<>"Abierta",$N9=""),"Falta fecha cierre",IF(AND(OR($M9="Cerrada",$M9="Rolada"),$O9=""),"Falta prima cierre",IF(AND($N9<>"",$N9<$B9),"Cierre anterior a apertura",IF(AND($M9="Asignada",$R9=""),"Asignada: falta ID lote acciones",IF(AND($R9<>"",ISNA(MATCH($R9,Acciones!$A$2:$A$201,0))),"El ID lote no existe en Acciones",IF($AD9="","Revisa capital en riesgo","OK")))))))))
I10: 100 | T10: =IF($C10="","",IFERROR(INDEX(Listas!$B$2:$B$20,MATCH($D10,Listas!$A$2:$A$20,0)),"")) | U10: =IF($C10="","",IFERROR(INDEX(Listas!$C$2:$C$20,MATCH($D10,Listas!$A$2:$A$20,0)),"")) | V10: =IF($C10="","",IFERROR(INDEX(Listas!$D$2:$D$20,MATCH($D10,Listas!$A$2:$A$20,0)),"")) | W10: =IF(OR($C10="",$B10="",$G10=""),"",$G10-$B10) | X10: =IF(OR($C10="",$B10=""),"",IF($N10<>"",$N10,TODAY())-$B10) | Y10: =IF(OR($C10="",$M10<>"Abierta",$G10=""),"",MAX($G10-TODAY(),0)) | Z10: =IF($C10="","",N($K10)*N($H10)*N($I10)*IF($U10="Débito",-1,1)) | AA10: =IF($C10="","",IF(AND($U10="Débito",$F10<>""),$F10,$E10)) | AB10: =IF(OR($C10="",$T10="Mixta",$AA10=""),"",IF($V10="Subyacente",IF($J10="","",$J10-$K10),IF($T10="Put",$AA10-$K10,$AA10+$K10))) | AC10: =IF(OR($C10="",$T10="Mixta",$J10="",$AA10=""),"",IF($T10="Put",($J10-$AA10)/$J10,($AA10-$J10)/$J10)) | AD10: =IF($C10="","",IF($Q10<>"",$Q10,IF($V10="Strike",N($E10)*$H10*$I10,IF($V10="Subyacente",IF($J10="","",$J10*$H10*$I10),IF($V10="Ancho",IF($F10="","",ABS($E10-$F10)*$H10*$I10-$K10*$H10*$I10),IF($V10="Prima",$K10*$H10*$I10,"")))))) | AE10: =IF(OR($C10="",$M10="Abierta",$M10=""),"",(N($K10)-IF(OR($M10="Cerrada",$M10="Rolada"),N($O10),0))*$H10*$I10*IF($U10="Débito",-1,1)-N($L10)-N($P10)) | AF10: =IF(OR($AE10="",$AD10=""),"",IF($AD10<=0,"",$AE10/$AD10)) | AG10: =IF($AF10="","",$AF10*365/MAX(N($X10),1)) | AH10: =IF(OR($C10="",$U10<>"Crédito",$AD10=""),"",IF($AD10<=0,"",($Z10-N($L10))/$AD10)) | AI10: =IF(OR($AH10="",$W10=""),"",$AH10*365/MAX($W10,1)) | AJ10: =IF(OR($AE10="",$U10<>"Crédito",N($K10)=0),"",(N($K10)-IF(OR($M10="Cerrada",$M10="Rolada"),N($O10),0))/$K10) | AK10: =IF(OR($C10="",$N10=""),"",DATE(YEAR($N10),MONTH($N10),1)) | AL10: =IF($C10="","",IF($M10="Abierta",0,1)) | AM10: =IF(OR($AE10="",$AD10=""),"",$AD10*MAX(N($X10),1)) | AN10: =IF($C10="","",IF(OR($B10="",$D10="",$H10="",$K10="",$M10=""),"Faltan datos obligatorios",IF($T10="","Estrategia no reconocida",IF(AND($M10<>"Abierta",$N10=""),"Falta fecha cierre",IF(AND(OR($M10="Cerrada",$M10="Rolada"),$O10=""),"Falta prima cierre",IF(AND($N10<>"",$N10<$B10),"Cierre anterior a apertura",IF(AND($M10="Asignada",$R10=""),"Asignada: falta ID lote acciones",IF(AND($R10<>"",ISNA(MATCH($R10,Acciones!$A$2:$A$201,0))),"El ID lote no existe en Acciones",IF($AD10="","Revisa capital en riesgo","OK")))))))))
I11: 100 | T11: =IF($C11="","",IFERROR(INDEX(Listas!$B$2:$B$20,MATCH($D11,Listas!$A$2:$A$20,0)),"")) | U11: =IF($C11="","",IFERROR(INDEX(Listas!$C$2:$C$20,MATCH($D11,Listas!$A$2:$A$20,0)),"")) | V11: =IF($C11="","",IFERROR(INDEX(Listas!$D$2:$D$20,MATCH($D11,Listas!$A$2:$A$20,0)),"")) | W11: =IF(OR($C11="",$B11="",$G11=""),"",$G11-$B11) | X11: =IF(OR($C11="",$B11=""),"",IF($N11<>"",$N11,TODAY())-$B11) | Y11: =IF(OR($C11="",$M11<>"Abierta",$G11=""),"",MAX($G11-TODAY(),0)) | Z11: =IF($C11="","",N($K11)*N($H11)*N($I11)*IF($U11="Débito",-1,1)) | AA11: =IF($C11="","",IF(AND($U11="Débito",$F11<>""),$F11,$E11)) | AB11: =IF(OR($C11="",$T11="Mixta",$AA11=""),"",IF($V11="Subyacente",IF($J11="","",$J11-$K11),IF($T11="Put",$AA11-$K11,$AA11+$K11))) | AC11: =IF(OR($C11="",$T11="Mixta",$J11="",$AA11=""),"",IF($T11="Put",($J11-$AA11)/$J11,($AA11-$J11)/$J11)) | AD11: =IF($C11="","",IF($Q11<>"",$Q11,IF($V11="Strike",N($E11)*$H11*$I11,IF($V11="Subyacente",IF($J11="","",$J11*$H11*$I11),IF($V11="Ancho",IF($F11="","",ABS($E11-$F11)*$H11*$I11-$K11*$H11*$I11),IF($V11="Prima",$K11*$H11*$I11,"")))))) | AE11: =IF(OR($C11="",$M11="Abierta",$M11=""),"",(N($K11)-IF(OR($M11="Cerrada",$M11="Rolada"),N($O11),0))*$H11*$I11*IF($U11="Débito",-1,1)-N($L11)-N($P11)) | AF11: =IF(OR($AE11="",$AD11=""),"",IF($AD11<=0,"",$AE11/$AD11)) | AG11: =IF($AF11="","",$AF11*365/MAX(N($X11),1)) | AH11: =IF(OR($C11="",$U11<>"Crédito",$AD11=""),"",IF($AD11<=0,"",($Z11-N($L11))/$AD11)) | AI11: =IF(OR($AH11="",$W11=""),"",$AH11*365/MAX($W11,1)) | AJ11: =IF(OR($AE11="",$U11<>"Crédito",N($K11)=0),"",(N($K11)-IF(OR($M11="Cerrada",$M11="Rolada"),N($O11),0))/$K11) | AK11: =IF(OR($C11="",$N11=""),"",DATE(YEAR($N11),MONTH($N11),1)) | AL11: =IF($C11="","",IF($M11="Abierta",0,1)) | AM11: =IF(OR($AE11="",$AD11=""),"",$AD11*MAX(N($X11),1)) | AN11: =IF($C11="","",IF(OR($B11="",$D11="",$H11="",$K11="",$M11=""),"Faltan datos obligatorios",IF($T11="","Estrategia no reconocida",IF(AND($M11<>"Abierta",$N11=""),"Falta fecha cierre",IF(AND(OR($M11="Cerrada",$M11="Rolada"),$O11=""),"Falta prima cierre",IF(AND($N11<>"",$N11<$B11),"Cierre anterior a apertura",IF(AND($M11="Asignada",$R11=""),"Asignada: falta ID lote acciones",IF(AND($R11<>"",ISNA(MATCH($R11,Acciones!$A$2:$A$201,0))),"El ID lote no existe en Acciones",IF($AD11="","Revisa capital en riesgo","OK")))))))))
I12: 100 | T12: =IF($C12="","",IFERROR(INDEX(Listas!$B$2:$B$20,MATCH($D12,Listas!$A$2:$A$20,0)),"")) | U12: =IF($C12="","",IFERROR(INDEX(Listas!$C$2:$C$20,MATCH($D12,Listas!$A$2:$A$20,0)),"")) | V12: =IF($C12="","",IFERROR(INDEX(Listas!$D$2:$D$20,MATCH($D12,Listas!$A$2:$A$20,0)),"")) | W12: =IF(OR($C12="",$B12="",$G12=""),"",$G12-$B12) | X12: =IF(OR($C12="",$B12=""),"",IF($N12<>"",$N12,TODAY())-$B12) | Y12: =IF(OR($C12="",$M12<>"Abierta",$G12=""),"",MAX($G12-TODAY(),0)) | Z12: =IF($C12="","",N($K12)*N($H12)*N($I12)*IF($U12="Débito",-1,1)) | AA12: =IF($C12="","",IF(AND($U12="Débito",$F12<>""),$F12,$E12)) | AB12: =IF(OR($C12="",$T12="Mixta",$AA12=""),"",IF($V12="Subyacente",IF($J12="","",$J12-$K12),IF($T12="Put",$AA12-$K12,$AA12+$K12))) | AC12: =IF(OR($C12="",$T12="Mixta",$J12="",$AA12=""),"",IF($T12="Put",($J12-$AA12)/$J12,($AA12-$J12)/$J12)) | AD12: =IF($C12="","",IF($Q12<>"",$Q12,IF($V12="Strike",N($E12)*$H12*$I12,IF($V12="Subyacente",IF($J12="","",$J12*$H12*$I12),IF($V12="Ancho",IF($F12="","",ABS($E12-$F12)*$H12*$I12-$K12*$H12*$I12),IF($V12="Prima",$K12*$H12*$I12,"")))))) | AE12: =IF(OR($C12="",$M12="Abierta",$M12=""),"",(N($K12)-IF(OR($M12="Cerrada",$M12="Rolada"),N($O12),0))*$H12*$I12*IF($U12="Débito",-1,1)-N($L12)-N($P12)) | AF12: =IF(OR($AE12="",$AD12=""),"",IF($AD12<=0,"",$AE12/$AD12)) | AG12: =IF($AF12="","",$AF12*365/MAX(N($X12),1)) | AH12: =IF(OR($C12="",$U12<>"Crédito",$AD12=""),"",IF($AD12<=0,"",($Z12-N($L12))/$AD12)) | AI12: =IF(OR($AH12="",$W12=""),"",$AH12*365/MAX($W12,1)) | AJ12: =IF(OR($AE12="",$U12<>"Crédito",N($K12)=0),"",(N($K12)-IF(OR($M12="Cerrada",$M12="Rolada"),N($O12),0))/$K12) | AK12: =IF(OR($C12="",$N12=""),"",DATE(YEAR($N12),MONTH($N12),1)) | AL12: =IF($C12="","",IF($M12="Abierta",0,1)) | AM12: =IF(OR($AE12="",$AD12=""),"",$AD12*MAX(N($X12),1)) | AN12: =IF($C12="","",IF(OR($B12="",$D12="",$H12="",$K12="",$M12=""),"Faltan datos obligatorios",IF($T12="","Estrategia no reconocida",IF(AND($M12<>"Abierta",$N12=""),"Falta fecha cierre",IF(AND(OR($M12="Cerrada",$M12="Rolada"),$O12=""),"Falta prima cierre",IF(AND($N12<>"",$N12<$B12),"Cierre anterior a apertura",IF(AND($M12="Asignada",$R12=""),"Asignada: falta ID lote acciones",IF(AND($R12<>"",ISNA(MATCH($R12,Acciones!$A$2:$A$201,0))),"El ID lote no existe en Acciones",IF($AD12="","Revisa capital en riesgo","OK")))))))))
I13: 100 | T13: =IF($C13="","",IFERROR(INDEX(Listas!$B$2:$B$20,MATCH($D13,Listas!$A$2:$A$20,0)),"")) | U13: =IF($C13="","",IFERROR(INDEX(Listas!$C$2:$C$20,MATCH($D13,Listas!$A$2:$A$20,0)),"")) | V13: =IF($C13="","",IFERROR(INDEX(Listas!$D$2:$D$20,MATCH($D13,Listas!$A$2:$A$20,0)),"")) | W13: =IF(OR($C13="",$B13="",$G13=""),"",$G13-$B13) | X13: =IF(OR($C13="",$B13=""),"",IF($N13<>"",$N13,TODAY())-$B13) | Y13: =IF(OR($C13="",$M13<>"Abierta",$G13=""),"",MAX($G13-TODAY(),0)) | Z13: =IF($C13="","",N($K13)*N($H13)*N($I13)*IF($U13="Débito",-1,1)) | AA13: =IF($C13="","",IF(AND($U13="Débito",$F13<>""),$F13,$E13)) | AB13: =IF(OR($C13="",$T13="Mixta",$AA13=""),"",IF($V13="Subyacente",IF($J13="","",$J13-$K13),IF($T13="Put",$AA13-$K13,$AA13+$K13))) | AC13: =IF(OR($C13="",$T13="Mixta",$J13="",$AA13=""),"",IF($T13="Put",($J13-$AA13)/$J13,($AA13-$J13)/$J13)) | AD13: =IF($C13="","",IF($Q13<>"",$Q13,IF($V13="Strike",N($E13)*$H13*$I13,IF($V13="Subyacente",IF($J13="","",$J13*$H13*$I13),IF($V13="Ancho",IF($F13="","",ABS($E13-$F13)*$H13*$I13-$K13*$H13*$I13),IF($V13="Prima",$K13*$H13*$I13,"")))))) | AE13: =IF(OR($C13="",$M13="Abierta",$M13=""),"",(N($K13)-IF(OR($M13="Cerrada",$M13="Rolada"),N($O13),0))*$H13*$I13*IF($U13="Débito",-1,1)-N($L13)-N($P13)) | AF13: =IF(OR($AE13="",$AD13=""),"",IF($AD13<=0,"",$AE13/$AD13)) | AG13: =IF($AF13="","",$AF13*365/MAX(N($X13),1)) | AH13: =IF(OR($C13="",$U13<>"Crédito",$AD13=""),"",IF($AD13<=0,"",($Z13-N($L13))/$AD13)) | AI13: =IF(OR($AH13="",$W13=""),"",$AH13*365/MAX($W13,1)) | AJ13: =IF(OR($AE13="",$U13<>"Crédito",N($K13)=0),"",(N($K13)-IF(OR($M13="Cerrada",$M13="Rolada"),N($O13),0))/$K13) | AK13: =IF(OR($C13="",$N13=""),"",DATE(YEAR($N13),MONTH($N13),1)) | AL13: =IF($C13="","",IF($M13="Abierta",0,1)) | AM13: =IF(OR($AE13="",$AD13=""),"",$AD13*MAX(N($X13),1)) | AN13: =IF($C13="","",IF(OR($B13="",$D13="",$H13="",$K13="",$M13=""),"Faltan datos obligatorios",IF($T13="","Estrategia no reconocida",IF(AND($M13<>"Abierta",$N13=""),"Falta fecha cierre",IF(AND(OR($M13="Cerrada",$M13="Rolada"),$O13=""),"Falta prima cierre",IF(AND($N13<>"",$N13<$B13),"Cierre anterior a apertura",IF(AND($M13="Asignada",$R13=""),"Asignada: falta ID lote acciones",IF(AND($R13<>"",ISNA(MATCH($R13,Acciones!$A$2:$A$201,0))),"El ID lote no existe en Acciones",IF($AD13="","Revisa capital en riesgo","OK")))))))))
I14: 100 | T14: =IF($C14="","",IFERROR(INDEX(Listas!$B$2:$B$20,MATCH($D14,Listas!$A$2:$A$20,0)),"")) | U14: =IF($C14="","",IFERROR(INDEX(Listas!$C$2:$C$20,MATCH($D14,Listas!$A$2:$A$20,0)),"")) | V14: =IF($C14="","",IFERROR(INDEX(Listas!$D$2:$D$20,MATCH($D14,Listas!$A$2:$A$20,0)),"")) | W14: =IF(OR($C14="",$B14="",$G14=""),"",$G14-$B14) | X14: =IF(OR($C14="",$B14=""),"",IF($N14<>"",$N14,TODAY())-$B14) | Y14: =IF(OR($C14="",$M14<>"Abierta",$G14=""),"",MAX($G14-TODAY(),0)) | Z14: =IF($C14="","",N($K14)*N($H14)*N($I14)*IF($U14="Débito",-1,1)) | AA14: =IF($C14="","",IF(AND($U14="Débito",$F14<>""),$F14,$E14)) | AB14: =IF(OR($C14="",$T14="Mixta",$AA14=""),"",IF($V14="Subyacente",IF($J14="","",$J14-$K14),IF($T14="Put",$AA14-$K14,$AA14+$K14))) | AC14: =IF(OR($C14="",$T14="Mixta",$J14="",$AA14=""),"",IF($T14="Put",($J14-$AA14)/$J14,($AA14-$J14)/$J14)) | AD14: =IF($C14="","",IF($Q14<>"",$Q14,IF($V14="Strike",N($E14)*$H14*$I14,IF($V14="Subyacente",IF($J14="","",$J14*$H14*$I14),IF($V14="Ancho",IF($F14="","",ABS($E14-$F14)*$H14*$I14-$K14*$H14*$I14),IF($V14="Prima",$K14*$H14*$I14,"")))))) | AE14: =IF(OR($C14="",$M14="Abierta",$M14=""),"",(N($K14)-IF(OR($M14="Cerrada",$M14="Rolada"),N($O14),0))*$H14*$I14*IF($U14="Débito",-1,1)-N($L14)-N($P14)) | AF14: =IF(OR($AE14="",$AD14=""),"",IF($AD14<=0,"",$AE14/$AD14)) | AG14: =IF($AF14="","",$AF14*365/MAX(N($X14),1)) | AH14: =IF(OR($C14="",$U14<>"Crédito",$AD14=""),"",IF($AD14<=0,"",($Z14-N($L14))/$AD14)) | AI14: =IF(OR($AH14="",$W14=""),"",$AH14*365/MAX($W14,1)) | AJ14: =IF(OR($AE14="",$U14<>"Crédito",N($K14)=0),"",(N($K14)-IF(OR($M14="Cerrada",$M14="Rolada"),N($O14),0))/$K14) | AK14: =IF(OR($C14="",$N14=""),"",DATE(YEAR($N14),MONTH($N14),1)) | AL14: =IF($C14="","",IF($M14="Abierta",0,1)) | AM14: =IF(OR($AE14="",$AD14=""),"",$AD14*MAX(N($X14),1)) | AN14: =IF($C14="","",IF(OR($B14="",$D14="",$H14="",$K14="",$M14=""),"Faltan datos obligatorios",IF($T14="","Estrategia no reconocida",IF(AND($M14<>"Abierta",$N14=""),"Falta fecha cierre",IF(AND(OR($M14="Cerrada",$M14="Rolada"),$O14=""),"Falta prima cierre",IF(AND($N14<>"",$N14<$B14),"Cierre anterior a apertura",IF(AND($M14="Asignada",$R14=""),"Asignada: falta ID lote acciones",IF(AND($R14<>"",ISNA(MATCH($R14,Acciones!$A$2:$A$201,0))),"El ID lote no existe en Acciones",IF($AD14="","Revisa capital en riesgo","OK")))))))))
I15: 100 | T15: =IF($C15="","",IFERROR(INDEX(Listas!$B$2:$B$20,MATCH($D15,Listas!$A$2:$A$20,0)),"")) | U15: =IF($C15="","",IFERROR(INDEX(Listas!$C$2:$C$20,MATCH($D15,Listas!$A$2:$A$20,0)),"")) | V15: =IF($C15="","",IFERROR(INDEX(Listas!$D$2:$D$20,MATCH($D15,Listas!$A$2:$A$20,0)),"")) | W15: =IF(OR($C15="",$B15="",$G15=""),"",$G15-$B15) | X15: =IF(OR($C15="",$B15=""),"",IF($N15<>"",$N15,TODAY())-$B15) | Y15: =IF(OR($C15="",$M15<>"Abierta",$G15=""),"",MAX($G15-TODAY(),0)) | Z15: =IF($C15="","",N($K15)*N($H15)*N($I15)*IF($U15="Débito",-1,1)) | AA15: =IF($C15="","",IF(AND($U15="Débito",$F15<>""),$F15,$E15)) | AB15: =IF(OR($C15="",$T15="Mixta",$AA15=""),"",IF($V15="Subyacente",IF($J15="","",$J15-$K15),IF($T15="Put",$AA15-$K15,$AA15+$K15))) | AC15: =IF(OR($C15="",$T15="Mixta",$J15="",$AA15=""),"",IF($T15="Put",($J15-$AA15)/$J15,($AA15-$J15)/$J15)) | AD15: =IF($C15="","",IF($Q15<>"",$Q15,IF($V15="Strike",N($E15)*$H15*$I15,IF($V15="Subyacente",IF($J15="","",$J15*$H15*$I15),IF($V15="Ancho",IF($F15="","",ABS($E15-$F15)*$H15*$I15-$K15*$H15*$I15),IF($V15="Prima",$K15*$H15*$I15,"")))))) | AE15: =IF(OR($C15="",$M15="Abierta",$M15=""),"",(N($K15)-IF(OR($M15="Cerrada",$M15="Rolada"),N($O15),0))*$H15*$I15*IF($U15="Débito",-1,1)-N($L15)-N($P15)) | AF15: =IF(OR($AE15="",$AD15=""),"",IF($AD15<=0,"",$AE15/$AD15)) | AG15: =IF($AF15="","",$AF15*365/MAX(N($X15),1)) | AH15: =IF(OR($C15="",$U15<>"Crédito",$AD15=""),"",IF($AD15<=0,"",($Z15-N($L15))/$AD15)) | AI15: =IF(OR($AH15="",$W15=""),"",$AH15*365/MAX($W15,1)) | AJ15: =IF(OR($AE15="",$U15<>"Crédito",N($K15)=0),"",(N($K15)-IF(OR($M15="Cerrada",$M15="Rolada"),N($O15),0))/$K15) | AK15: =IF(OR($C15="",$N15=""),"",DATE(YEAR($N15),MONTH($N15),1)) | AL15: =IF($C15="","",IF($M15="Abierta",0,1)) | AM15: =IF(OR($AE15="",$AD15=""),"",$AD15*MAX(N($X15),1)) | AN15: =IF($C15="","",IF(OR($B15="",$D15="",$H15="",$K15="",$M15=""),"Faltan datos obligatorios",IF($T15="","Estrategia no reconocida",IF(AND($M15<>"Abierta",$N15=""),"Falta fecha cierre",IF(AND(OR($M15="Cerrada",$M15="Rolada"),$O15=""),"Falta prima cierre",IF(AND($N15<>"",$N15<$B15),"Cierre anterior a apertura",IF(AND($M15="Asignada",$R15=""),"Asignada: falta ID lote acciones",IF(AND($R15<>"",ISNA(MATCH($R15,Acciones!$A$2:$A$201,0))),"El ID lote no existe en Acciones",IF($AD15="","Revisa capital en riesgo","OK")))))))))
I16: 100 | T16: =IF($C16="","",IFERROR(INDEX(Listas!$B$2:$B$20,MATCH($D16,Listas!$A$2:$A$20,0)),"")) | U16: =IF($C16="","",IFERROR(INDEX(Listas!$C$2:$C$20,MATCH($D16,Listas!$A$2:$A$20,0)),"")) | V16: =IF($C16="","",IFERROR(INDEX(Listas!$D$2:$D$20,MATCH($D16,Listas!$A$2:$A$20,0)),"")) | W16: =IF(OR($C16="",$B16="",$G16=""),"",$G16-$B16) | X16: =IF(OR($C16="",$B16=""),"",IF($N16<>"",$N16,TODAY())-$B16) | Y16: =IF(OR($C16="",$M16<>"Abierta",$G16=""),"",MAX($G16-TODAY(),0)) | Z16: =IF($C16="","",N($K16)*N($H16)*N($I16)*IF($U16="Débito",-1,1)) | AA16: =IF($C16="","",IF(AND($U16="Débito",$F16<>""),$F16,$E16)) | AB16: =IF(OR($C16="",$T16="Mixta",$AA16=""),"",IF($V16="Subyacente",IF($J16="","",$J16-$K16),IF($T16="Put",$AA16-$K16,$AA16+$K16))) | AC16: =IF(OR($C16="",$T16="Mixta",$J16="",$AA16=""),"",IF($T16="Put",($J16-$AA16)/$J16,($AA16-$J16)/$J16)) | AD16: =IF($C16="","",IF($Q16<>"",$Q16,IF($V16="Strike",N($E16)*$H16*$I16,IF($V16="Subyacente",IF($J16="","",$J16*$H16*$I16),IF($V16="Ancho",IF($F16="","",ABS($E16-$F16)*$H16*$I16-$K16*$H16*$I16),IF($V16="Prima",$K16*$H16*$I16,"")))))) | AE16: =IF(OR($C16="",$M16="Abierta",$M16=""),"",(N($K16)-IF(OR($M16="Cerrada",$M16="Rolada"),N($O16),0))*$H16*$I16*IF($U16="Débito",-1,1)-N($L16)-N($P16)) | AF16: =IF(OR($AE16="",$AD16=""),"",IF($AD16<=0,"",$AE16/$AD16)) | AG16: =IF($AF16="","",$AF16*365/MAX(N($X16),1)) | AH16: =IF(OR($C16="",$U16<>"Crédito",$AD16=""),"",IF($AD16<=0,"",($Z16-N($L16))/$AD16)) | AI16: =IF(OR($AH16="",$W16=""),"",$AH16*365/MAX($W16,1)) | AJ16: =IF(OR($AE16="",$U16<>"Crédito",N($K16)=0),"",(N($K16)-IF(OR($M16="Cerrada",$M16="Rolada"),N($O16),0))/$K16) | AK16: =IF(OR($C16="",$N16=""),"",DATE(YEAR($N16),MONTH($N16),1)) | AL16: =IF($C16="","",IF($M16="Abierta",0,1)) | AM16: =IF(OR($AE16="",$AD16=""),"",$AD16*MAX(N($X16),1)) | AN16: =IF($C16="","",IF(OR($B16="",$D16="",$H16="",$K16="",$M16=""),"Faltan datos obligatorios",IF($T16="","Estrategia no reconocida",IF(AND($M16<>"Abierta",$N16=""),"Falta fecha cierre",IF(AND(OR($M16="Cerrada",$M16="Rolada"),$O16=""),"Falta prima cierre",IF(AND($N16<>"",$N16<$B16),"Cierre anterior a apertura",IF(AND($M16="Asignada",$R16=""),"Asignada: falta ID lote acciones",IF(AND($R16<>"",ISNA(MATCH($R16,Acciones!$A$2:$A$201,0))),"El ID lote no existe en Acciones",IF($AD16="","Revisa capital en riesgo","OK")))))))))
I17: 100 | T17: =IF($C17="","",IFERROR(INDEX(Listas!$B$2:$B$20,MATCH($D17,Listas!$A$2:$A$20,0)),"")) | U17: =IF($C17="","",IFERROR(INDEX(Listas!$C$2:$C$20,MATCH($D17,Listas!$A$2:$A$20,0)),"")) | V17: =IF($C17="","",IFERROR(INDEX(Listas!$D$2:$D$20,MATCH($D17,Listas!$A$2:$A$20,0)),"")) | W17: =IF(OR($C17="",$B17="",$G17=""),"",$G17-$B17) | X17: =IF(OR($C17="",$B17=""),"",IF($N17<>"",$N17,TODAY())-$B17) | Y17: =IF(OR($C17="",$M17<>"Abierta",$G17=""),"",MAX($G17-TODAY(),0)) | Z17: =IF($C17="","",N($K17)*N($H17)*N($I17)*IF($U17="Débito",-1,1)) | AA17: =IF($C17="","",IF(AND($U17="Débito",$F17<>""),$F17,$E17)) | AB17: =IF(OR($C17="",$T17="Mixta",$AA17=""),"",IF($V17="Subyacente",IF($J17="","",$J17-$K17),IF($T17="Put",$AA17-$K17,$AA17+$K17))) | AC17: =IF(OR($C17="",$T17="Mixta",$J17="",$AA17=""),"",IF($T17="Put",($J17-$AA17)/$J17,($AA17-$J17)/$J17)) | AD17: =IF($C17="","",IF($Q17<>"",$Q17,IF($V17="Strike",N($E17)*$H17*$I17,IF($V17="Subyacente",IF($J17="","",$J17*$H17*$I17),IF($V17="Ancho",IF($F17="","",ABS($E17-$F17)*$H17*$I17-$K17*$H17*$I17),IF($V17="Prima",$K17*$H17*$I17,"")))))) | AE17: =IF(OR($C17="",$M17="Abierta",$M17=""),"",(N($K17)-IF(OR($M17="Cerrada",$M17="Rolada"),N($O17),0))*$H17*$I17*IF($U17="Débito",-1,1)-N($L17)-N($P17)) | AF17: =IF(OR($AE17="",$AD17=""),"",IF($AD17<=0,"",$AE17/$AD17)) | AG17: =IF($AF17="","",$AF17*365/MAX(N($X17),1)) | AH17: =IF(OR($C17="",$U17<>"Crédito",$AD17=""),"",IF($AD17<=0,"",($Z17-N($L17))/$AD17)) | AI17: =IF(OR($AH17="",$W17=""),"",$AH17*365/MAX($W17,1)) | AJ17: =IF(OR($AE17="",$U17<>"Crédito",N($K17)=0),"",(N($K17)-IF(OR($M17="Cerrada",$M17="Rolada"),N($O17),0))/$K17) | AK17: =IF(OR($C17="",$N17=""),"",DATE(YEAR($N17),MONTH($N17),1)) | AL17: =IF($C17="","",IF($M17="Abierta",0,1)) | AM17: =IF(OR($AE17="",$AD17=""),"",$AD17*MAX(N($X17),1)) | AN17: =IF($C17="","",IF(OR($B17="",$D17="",$H17="",$K17="",$M17=""),"Faltan datos obligatorios",IF($T17="","Estrategia no reconocida",IF(AND($M17<>"Abierta",$N17=""),"Falta fecha cierre",IF(AND(OR($M17="Cerrada",$M17="Rolada"),$O17=""),"Falta prima cierre",IF(AND($N17<>"",$N17<$B17),"Cierre anterior a apertura",IF(AND($M17="Asignada",$R17=""),"Asignada: falta ID lote acciones",IF(AND($R17<>"",ISNA(MATCH($R17,Acciones!$A$2:$A$201,0))),"El ID lote no existe en Acciones",IF($AD17="","Revisa capital en riesgo","OK")))))))))
I18: 100 | T18: =IF($C18="","",IFERROR(INDEX(Listas!$B$2:$B$20,MATCH($D18,Listas!$A$2:$A$20,0)),"")) | U18: =IF($C18="","",IFERROR(INDEX(Listas!$C$2:$C$20,MATCH($D18,Listas!$A$2:$A$20,0)),"")) | V18: =IF($C18="","",IFERROR(INDEX(Listas!$D$2:$D$20,MATCH($D18,Listas!$A$2:$A$20,0)),"")) | W18: =IF(OR($C18="",$B18="",$G18=""),"",$G18-$B18) | X18: =IF(OR($C18="",$B18=""),"",IF($N18<>"",$N18,TODAY())-$B18) | Y18: =IF(OR($C18="",$M18<>"Abierta",$G18=""),"",MAX($G18-TODAY(),0)) | Z18: =IF($C18="","",N($K18)*N($H18)*N($I18)*IF($U18="Débito",-1,1)) | AA18: =IF($C18="","",IF(AND($U18="Débito",$F18<>""),$F18,$E18)) | AB18: =IF(OR($C18="",$T18="Mixta",$AA18=""),"",IF($V18="Subyacente",IF($J18="","",$J18-$K18),IF($T18="Put",$AA18-$K18,$AA18+$K18))) | AC18: =IF(OR($C18="",$T18="Mixta",$J18="",$AA18=""),"",IF($T18="Put",($J18-$AA18)/$J18,($AA18-$J18)/$J18)) | AD18: =IF($C18="","",IF($Q18<>"",$Q18,IF($V18="Strike",N($E18)*$H18*$I18,IF($V18="Subyacente",IF($J18="","",$J18*$H18*$I18),IF($V18="Ancho",IF($F18="","",ABS($E18-$F18)*$H18*$I18-$K18*$H18*$I18),IF($V18="Prima",$K18*$H18*$I18,"")))))) | AE18: =IF(OR($C18="",$M18="Abierta",$M18=""),"",(N($K18)-IF(OR($M18="Cerrada",$M18="Rolada"),N($O18),0))*$H18*$I18*IF($U18="Débito",-1,1)-N($L18)-N($P18)) | AF18: =IF(OR($AE18="",$AD18=""),"",IF($AD18<=0,"",$AE18/$AD18)) | AG18: =IF($AF18="","",$AF18*365/MAX(N($X18),1)) | AH18: =IF(OR($C18="",$U18<>"Crédito",$AD18=""),"",IF($AD18<=0,"",($Z18-N($L18))/$AD18)) | AI18: =IF(OR($AH18="",$W18=""),"",$AH18*365/MAX($W18,1)) | AJ18: =IF(OR($AE18="",$U18<>"Crédito",N($K18)=0),"",(N($K18)-IF(OR($M18="Cerrada",$M18="Rolada"),N($O18),0))/$K18) | AK18: =IF(OR($C18="",$N18=""),"",DATE(YEAR($N18),MONTH($N18),1)) | AL18: =IF($C18="","",IF($M18="Abierta",0,1)) | AM18: =IF(OR($AE18="",$AD18=""),"",$AD18*MAX(N($X18),1)) | AN18: =IF($C18="","",IF(OR($B18="",$D18="",$H18="",$K18="",$M18=""),"Faltan datos obligatorios",IF($T18="","Estrategia no reconocida",IF(AND($M18<>"Abierta",$N18=""),"Falta fecha cierre",IF(AND(OR($M18="Cerrada",$M18="Rolada"),$O18=""),"Falta prima cierre",IF(AND($N18<>"",$N18<$B18),"Cierre anterior a apertura",IF(AND($M18="Asignada",$R18=""),"Asignada: falta ID lote acciones",IF(AND($R18<>"",ISNA(MATCH($R18,Acciones!$A$2:$A$201,0))),"El ID lote no existe en Acciones",IF($AD18="","Revisa capital en riesgo","OK")))))))))
... I1001: 100 | T1001: =IF($C1001="","",IFERROR(INDEX(Listas!$B$2:$B$20,MATCH($D1001,Listas!$A$2:$A$20,0)),"")) | U1001: =IF($C1001="","",IFERROR(INDEX(Listas!$C$2:$C$20,MATCH($D1001,Listas!$A$2:$A$20,0)),"")) | V1001: =IF($C1001="","",IFERROR(INDEX(Listas!$D$2:$D$20,MATCH($D1001,Listas!$A$2:$A$20,0)),"")) | W1001: =IF(OR($C1001="",$B1001="",$G1001=""),"",$G1001-$B1001) | X1001: =IF(OR($C1001="",$B1001=""),"",IF($N1001<>"",$N1001,TODAY())-$B1001) | Y1001: =IF(OR($C1001="",$M1001<>"Abierta",$G1001=""),"",MAX($G1001-TODAY(),0)) | Z1001: =IF($C1001="","",N($K1001)*N($H1001)*N($I1001)*IF($U1001="Débito",-1,1)) | AA1001: =IF($C1001="","",IF(AND($U1001="Débito",$F1001<>""),$F1001,$E1001)) | AB1001: =IF(OR($C1001="",$T1001="Mixta",$AA1001=""),"",IF($V1001="Subyacente",IF($J1001="","",$J1001-$K1001),IF($T1001="Put",$AA1001-$K1001,$AA1001+$K1001))) | AC1001: =IF(OR($C1001="",$T1001="Mixta",$J1001="",$AA1001=""),"",IF($T1001="Put",($J1001-$AA1001)/$J1001,($AA1001-$J1001)/$J1001)) | AD1001: =IF($C1001="","",IF($Q1001<>"",$Q1001,IF($V1001="Strike",N($E1001)*$H1001*$I1001,IF($V1001="Subyacente",IF($J1001="","",$J1001*$H1001*$I1001),IF($V1001="Ancho",IF($F1001="","",ABS($E1001-$F1001)*$H1001*$I1001-$K1001*$H1001*$I1001),IF($V1001="Prima",$K1001*$H1001*$I1001,"")))))) | AE1001: =IF(OR($C1001="",$M1001="Abierta",$M1001=""),"",(N($K1001)-IF(OR($M1001="Cerrada",$M1001="Rolada"),N($O1001),0))*$H1001*$I1001*IF($U1001="Débito",-1,1)-N($L1001)-N($P1001)) | AF1001: =IF(OR($AE1001="",$AD1001=""),"",IF($AD1001<=0,"",$AE1001/$AD1001)) | AG1001: =IF($AF1001="","",$AF1001*365/MAX(N($X1001),1)) | AH1001: =IF(OR($C1001="",$U1001<>"Crédito",$AD1001=""),"",IF($AD1001<=0,"",($Z1001-N($L1001))/$AD1001)) | AI1001: =IF(OR($AH1001="",$W1001=""),"",$AH1001*365/MAX($W1001,1)) | AJ1001: =IF(OR($AE1001="",$U1001<>"Crédito",N($K1001)=0),"",(N($K1001)-IF(OR($M1001="Cerrada",$M1001="Rolada"),N($O1001),0))/$K1001) | AK1001: =IF(OR($C1001="",$N1001=""),"",DATE(YEAR($N1001),MONTH($N1001),1)) | AL1001: =IF($C1001="","",IF($M1001="Abierta",0,1)) | AM1001: =IF(OR($AE1001="",$AD1001=""),"",$AD1001*MAX(N($X1001),1)) | AN1001: =IF($C1001="","",IF(OR($B1001="",$D1001="",$H1001="",$K1001="",$M1001=""),"Faltan datos obligatorios",IF($T1001="","Estrategia no reconocida",IF(AND($M1001<>"Abierta",$N1001=""),"Falta fecha cierre",IF(AND(OR($M1001="Cerrada",$M1001="Rolada"),$O1001=""),"Falta prima cierre",IF(AND($N1001<>"",$N1001<$B1001),"Cierre anterior a apertura",IF(AND($M1001="Asignada",$R1001=""),"Asignada: falta ID lote acciones",IF(AND($R1001<>"",ISNA(MATCH($R1001,Acciones!$A$2:$A$201,0))),"El ID lote no existe en Acciones",IF($AD1001="","Revisa capital en riesgo","OK")))))))))

Sheet Acciones
A1: ID lote | B1: Activo | C1: Origen | D1: ID operación origen | E1: Fecha entrada | F1: Nº acciones | G1: Precio entrada (por acción) | H1: Comisiones entrada $ | I1: Estado | J1: Fecha salida | K1: Precio salida (por acción) | L1: Comisiones salida $ | M1: Precio actual | N1: Notas | O1: Coste entrada $ | P1: Días en cartera | Q1: Resultado acciones realizado $ | R1: Plusvalía latente $ | S1: Dividendos netos $ | T1: Primas asociadas $ | U1: Resultado total ciclo $ | V1: Coste base ajustado (por acción) | W1: Rentabilidad ciclo % | X1: ARORC ciclo % | Y1: Control
A2: L1 | B2: KO | C2: Asignación put | D2: 4 | E2: 46283 | F2: 100 | G2: 65 | H2: 0 | I2: En cartera | M2: 66.2 | N2: EJEMPLO · borrar esta fila | O2: =IF($B2="","",N($F2)*N($G2)+N($H2)) -> 6500 | P2: =IF(OR($B2="",$E2=""),"",IF($J2<>"",$J2,TODAY())-$E2) -> 25 | Q2: =IF(OR($B2="",$I2="",$I2="En cartera"),"",($K2-$G2)*$F2-N($H2)-N($L2)) | R2: =IF(OR($B2="",$I2<>"En cartera",$M2=""),"",($M2-$G2)*$F2-N($H2)) -> 120 | S2: =IF($B2="","",SUMIFS(Dividendos!$I$2:$I$301,Dividendos!$C$2:$C$301,$A2)) -> 43.35 | T2: =IF($B2="","",SUMIFS(Operaciones!$AE$2:$AE$1001,Operaciones!$R$2:$R$1001,$A2)) -> 78.95 | U2: =IF($B2="","",N($Q2)+$S2+$T2) -> 122.3 | V2: =IF(OR($B2="",N($F2)=0),"",(N($F2)*N($G2)-$S2-$T2)/$F2) -> 63.777 | W2: =IF(OR($B2="",N($F2)*N($G2)=0),"",$U2/($F2*$G2)) -> 0.018815385 | X2: =IF(OR($W2="",$P2=""),"",$W2*365/MAX($P2,1)) -> 0.27470462 | Y2: =IF($B2="","",IF(OR($A2="",$E2="",$F2="",$G2="",$I2=""),"Faltan datos obligatorios",IF(COUNTIF($A$2:$A$201,$A2)>1,"ID lote duplicado",IF(AND($I2<>"En cartera",OR($J2="",$K2="")),"Falta fecha o precio de salida",IF(AND($J2<>"",$J2<$E2),"Salida anterior a entrada",IF(AND($I2="En cartera",$M2=""),"OK (sin precio actual)","OK")))))) -> OK
O3: =IF($B3="","",N($F3)*N($G3)+N($H3)) | P3: =IF(OR($B3="",$E3=""),"",IF($J3<>"",$J3,TODAY())-$E3) | Q3: =IF(OR($B3="",$I3="",$I3="En cartera"),"",($K3-$G3)*$F3-N($H3)-N($L3)) | R3: =IF(OR($B3="",$I3<>"En cartera",$M3=""),"",($M3-$G3)*$F3-N($H3)) | S3: =IF($B3="","",SUMIFS(Dividendos!$I$2:$I$301,Dividendos!$C$2:$C$301,$A3)) | T3: =IF($B3="","",SUMIFS(Operaciones!$AE$2:$AE$1001,Operaciones!$R$2:$R$1001,$A3)) | U3: =IF($B3="","",N($Q3)+$S3+$T3) | V3: =IF(OR($B3="",N($F3)=0),"",(N($F3)*N($G3)-$S3-$T3)/$F3) | W3: =IF(OR($B3="",N($F3)*N($G3)=0),"",$U3/($F3*$G3)) | X3: =IF(OR($W3="",$P3=""),"",$W3*365/MAX($P3,1)) | Y3: =IF($B3="","",IF(OR($A3="",$E3="",$F3="",$G3="",$I3=""),"Faltan datos obligatorios",IF(COUNTIF($A$2:$A$201,$A3)>1,"ID lote duplicado",IF(AND($I3<>"En cartera",OR($J3="",$K3="")),"Falta fecha o precio de salida",IF(AND($J3<>"",$J3<$E3),"Salida anterior a entrada",IF(AND($I3="En cartera",$M3=""),"OK (sin precio actual)","OK"))))))
O4: =IF($B4="","",N($F4)*N($G4)+N($H4)) | P4: =IF(OR($B4="",$E4=""),"",IF($J4<>"",$J4,TODAY())-$E4) | Q4: =IF(OR($B4="",$I4="",$I4="En cartera"),"",($K4-$G4)*$F4-N($H4)-N($L4)) | R4: =IF(OR($B4="",$I4<>"En cartera",$M4=""),"",($M4-$G4)*$F4-N($H4)) | S4: =IF($B4="","",SUMIFS(Dividendos!$I$2:$I$301,Dividendos!$C$2:$C$301,$A4)) | T4: =IF($B4="","",SUMIFS(Operaciones!$AE$2:$AE$1001,Operaciones!$R$2:$R$1001,$A4)) | U4: =IF($B4="","",N($Q4)+$S4+$T4) | V4: =IF(OR($B4="",N($F4)=0),"",(N($F4)*N($G4)-$S4-$T4)/$F4) | W4: =IF(OR($B4="",N($F4)*N($G4)=0),"",$U4/($F4*$G4)) | X4: =IF(OR($W4="",$P4=""),"",$W4*365/MAX($P4,1)) | Y4: =IF($B4="","",IF(OR($A4="",$E4="",$F4="",$G4="",$I4=""),"Faltan datos obligatorios",IF(COUNTIF($A$2:$A$201,$A4)>1,"ID lote duplicado",IF(AND($I4<>"En cartera",OR($J4="",$K4="")),"Falta fecha o precio de salida",IF(AND($J4<>"",$J4<$E4),"Salida anterior a entrada",IF(AND($I4="En cartera",$M4=""),"OK (sin precio actual)","OK"))))))
O5: =IF($B5="","",N($F5)*N($G5)+N($H5)) | P5: =IF(OR($B5="",$E5=""),"",IF($J5<>"",$J5,TODAY())-$E5) | Q5: =IF(OR($B5="",$I5="",$I5="En cartera"),"",($K5-$G5)*$F5-N($H5)-N($L5)) | R5: =IF(OR($B5="",$I5<>"En cartera",$M5=""),"",($M5-$G5)*$F5-N($H5)) | S5: =IF($B5="","",SUMIFS(Dividendos!$I$2:$I$301,Dividendos!$C$2:$C$301,$A5)) | T5: =IF($B5="","",SUMIFS(Operaciones!$AE$2:$AE$1001,Operaciones!$R$2:$R$1001,$A5)) | U5: =IF($B5="","",N($Q5)+$S5+$T5) | V5: =IF(OR($B5="",N($F5)=0),"",(N($F5)*N($G5)-$S5-$T5)/$F5) | W5: =IF(OR($B5="",N($F5)*N($G5)=0),"",$U5/($F5*$G5)) | X5: =IF(OR($W5="",$P5=""),"",$W5*365/MAX($P5,1)) | Y5: =IF($B5="","",IF(OR($A5="",$E5="",$F5="",$G5="",$I5=""),"Faltan datos obligatorios",IF(COUNTIF($A$2:$A$201,$A5)>1,"ID lote duplicado",IF(AND($I5<>"En cartera",OR($J5="",$K5="")),"Falta fecha o precio de salida",IF(AND($J5<>"",$J5<$E5),"Salida anterior a entrada",IF(AND($I5="En cartera",$M5=""),"OK (sin precio actual)","OK"))))))
O6: =IF($B6="","",N($F6)*N($G6)+N($H6)) | P6: =IF(OR($B6="",$E6=""),"",IF($J6<>"",$J6,TODAY())-$E6) | Q6: =IF(OR($B6="",$I6="",$I6="En cartera"),"",($K6-$G6)*$F6-N($H6)-N($L6)) | R6: =IF(OR($B6="",$I6<>"En cartera",$M6=""),"",($M6-$G6)*$F6-N($H6)) | S6: =IF($B6="","",SUMIFS(Dividendos!$I$2:$I$301,Dividendos!$C$2:$C$301,$A6)) | T6: =IF($B6="","",SUMIFS(Operaciones!$AE$2:$AE$1001,Operaciones!$R$2:$R$1001,$A6)) | U6: =IF($B6="","",N($Q6)+$S6+$T6) | V6: =IF(OR($B6="",N($F6)=0),"",(N($F6)*N($G6)-$S6-$T6)/$F6) | W6: =IF(OR($B6="",N($F6)*N($G6)=0),"",$U6/($F6*$G6)) | X6: =IF(OR($W6="",$P6=""),"",$W6*365/MAX($P6,1)) | Y6: =IF($B6="","",IF(OR($A6="",$E6="",$F6="",$G6="",$I6=""),"Faltan datos obligatorios",IF(COUNTIF($A$2:$A$201,$A6)>1,"ID lote duplicado",IF(AND($I6<>"En cartera",OR($J6="",$K6="")),"Falta fecha o precio de salida",IF(AND($J6<>"",$J6<$E6),"Salida anterior a entrada",IF(AND($I6="En cartera",$M6=""),"OK (sin precio actual)","OK"))))))
O7: =IF($B7="","",N($F7)*N($G7)+N($H7)) | P7: =IF(OR($B7="",$E7=""),"",IF($J7<>"",$J7,TODAY())-$E7) | Q7: =IF(OR($B7="",$I7="",$I7="En cartera"),"",($K7-$G7)*$F7-N($H7)-N($L7)) | R7: =IF(OR($B7="",$I7<>"En cartera",$M7=""),"",($M7-$G7)*$F7-N($H7)) | S7: =IF($B7="","",SUMIFS(Dividendos!$I$2:$I$301,Dividendos!$C$2:$C$301,$A7)) | T7: =IF($B7="","",SUMIFS(Operaciones!$AE$2:$AE$1001,Operaciones!$R$2:$R$1001,$A7)) | U7: =IF($B7="","",N($Q7)+$S7+$T7) | V7: =IF(OR($B7="",N($F7)=0),"",(N($F7)*N($G7)-$S7-$T7)/$F7) | W7: =IF(OR($B7="",N($F7)*N($G7)=0),"",$U7/($F7*$G7)) | X7: =IF(OR($W7="",$P7=""),"",$W7*365/MAX($P7,1)) | Y7: =IF($B7="","",IF(OR($A7="",$E7="",$F7="",$G7="",$I7=""),"Faltan datos obligatorios",IF(COUNTIF($A$2:$A$201,$A7)>1,"ID lote duplicado",IF(AND($I7<>"En cartera",OR($J7="",$K7="")),"Falta fecha o precio de salida",IF(AND($J7<>"",$J7<$E7),"Salida anterior a entrada",IF(AND($I7="En cartera",$M7=""),"OK (sin precio actual)","OK"))))))
O8: =IF($B8="","",N($F8)*N($G8)+N($H8)) | P8: =IF(OR($B8="",$E8=""),"",IF($J8<>"",$J8,TODAY())-$E8) | Q8: =IF(OR($B8="",$I8="",$I8="En cartera"),"",($K8-$G8)*$F8-N($H8)-N($L8)) | R8: =IF(OR($B8="",$I8<>"En cartera",$M8=""),"",($M8-$G8)*$F8-N($H8)) | S8: =IF($B8="","",SUMIFS(Dividendos!$I$2:$I$301,Dividendos!$C$2:$C$301,$A8)) | T8: =IF($B8="","",SUMIFS(Operaciones!$AE$2:$AE$1001,Operaciones!$R$2:$R$1001,$A8)) | U8: =IF($B8="","",N($Q8)+$S8+$T8) | V8: =IF(OR($B8="",N($F8)=0),"",(N($F8)*N($G8)-$S8-$T8)/$F8) | W8: =IF(OR($B8="",N($F8)*N($G8)=0),"",$U8/($F8*$G8)) | X8: =IF(OR($W8="",$P8=""),"",$W8*365/MAX($P8,1)) | Y8: =IF($B8="","",IF(OR($A8="",$E8="",$F8="",$G8="",$I8=""),"Faltan datos obligatorios",IF(COUNTIF($A$2:$A$201,$A8)>1,"ID lote duplicado",IF(AND($I8<>"En cartera",OR($J8="",$K8="")),"Falta fecha o precio de salida",IF(AND($J8<>"",$J8<$E8),"Salida anterior a entrada",IF(AND($I8="En cartera",$M8=""),"OK (sin precio actual)","OK"))))))
O9: =IF($B9="","",N($F9)*N($G9)+N($H9)) | P9: =IF(OR($B9="",$E9=""),"",IF($J9<>"",$J9,TODAY())-$E9) | Q9: =IF(OR($B9="",$I9="",$I9="En cartera"),"",($K9-$G9)*$F9-N($H9)-N($L9)) | R9: =IF(OR($B9="",$I9<>"En cartera",$M9=""),"",($M9-$G9)*$F9-N($H9)) | S9: =IF($B9="","",SUMIFS(Dividendos!$I$2:$I$301,Dividendos!$C$2:$C$301,$A9)) | T9: =IF($B9="","",SUMIFS(Operaciones!$AE$2:$AE$1001,Operaciones!$R$2:$R$1001,$A9)) | U9: =IF($B9="","",N($Q9)+$S9+$T9) | V9: =IF(OR($B9="",N($F9)=0),"",(N($F9)*N($G9)-$S9-$T9)/$F9) | W9: =IF(OR($B9="",N($F9)*N($G9)=0),"",$U9/($F9*$G9)) | X9: =IF(OR($W9="",$P9=""),"",$W9*365/MAX($P9,1)) | Y9: =IF($B9="","",IF(OR($A9="",$E9="",$F9="",$G9="",$I9=""),"Faltan datos obligatorios",IF(COUNTIF($A$2:$A$201,$A9)>1,"ID lote duplicado",IF(AND($I9<>"En cartera",OR($J9="",$K9="")),"Falta fecha o precio de salida",IF(AND($J9<>"",$J9<$E9),"Salida anterior a entrada",IF(AND($I9="En cartera",$M9=""),"OK (sin precio actual)","OK"))))))
O10: =IF($B10="","",N($F10)*N($G10)+N($H10)) | P10: =IF(OR($B10="",$E10=""),"",IF($J10<>"",$J10,TODAY())-$E10) | Q10: =IF(OR($B10="",$I10="",$I10="En cartera"),"",($K10-$G10)*$F10-N($H10)-N($L10)) | R10: =IF(OR($B10="",$I10<>"En cartera",$M10=""),"",($M10-$G10)*$F10-N($H10)) | S10: =IF($B10="","",SUMIFS(Dividendos!$I$2:$I$301,Dividendos!$C$2:$C$301,$A10)) | T10: =IF($B10="","",SUMIFS(Operaciones!$AE$2:$AE$1001,Operaciones!$R$2:$R$1001,$A10)) | U10: =IF($B10="","",N($Q10)+$S10+$T10) | V10: =IF(OR($B10="",N($F10)=0),"",(N($F10)*N($G10)-$S10-$T10)/$F10) | W10: =IF(OR($B10="",N($F10)*N($G10)=0),"",$U10/($F10*$G10)) | X10: =IF(OR($W10="",$P10=""),"",$W10*365/MAX($P10,1)) | Y10: =IF($B10="","",IF(OR($A10="",$E10="",$F10="",$G10="",$I10=""),"Faltan datos obligatorios",IF(COUNTIF($A$2:$A$201,$A10)>1,"ID lote duplicado",IF(AND($I10<>"En cartera",OR($J10="",$K10="")),"Falta fecha o precio de salida",IF(AND($J10<>"",$J10<$E10),"Salida anterior a entrada",IF(AND($I10="En cartera",$M10=""),"OK (sin precio actual)","OK"))))))
O11: =IF($B11="","",N($F11)*N($G11)+N($H11)) | P11: =IF(OR($B11="",$E11=""),"",IF($J11<>"",$J11,TODAY())-$E11) | Q11: =IF(OR($B11="",$I11="",$I11="En cartera"),"",($K11-$G11)*$F11-N($H11)-N($L11)) | R11: =IF(OR($B11="",$I11<>"En cartera",$M11=""),"",($M11-$G11)*$F11-N($H11)) | S11: =IF($B11="","",SUMIFS(Dividendos!$I$2:$I$301,Dividendos!$C$2:$C$301,$A11)) | T11: =IF($B11="","",SUMIFS(Operaciones!$AE$2:$AE$1001,Operaciones!$R$2:$R$1001,$A11)) | U11: =IF($B11="","",N($Q11)+$S11+$T11) | V11: =IF(OR($B11="",N($F11)=0),"",(N($F11)*N($G11)-$S11-$T11)/$F11) | W11: =IF(OR($B11="",N($F11)*N($G11)=0),"",$U11/($F11*$G11)) | X11: =IF(OR($W11="",$P11=""),"",$W11*365/MAX($P11,1)) | Y11: =IF($B11="","",IF(OR($A11="",$E11="",$F11="",$G11="",$I11=""),"Faltan datos obligatorios",IF(COUNTIF($A$2:$A$201,$A11)>1,"ID lote duplicado",IF(AND($I11<>"En cartera",OR($J11="",$K11="")),"Falta fecha o precio de salida",IF(AND($J11<>"",$J11<$E11),"Salida anterior a entrada",IF(AND($I11="En cartera",$M11=""),"OK (sin precio actual)","OK"))))))
O12: =IF($B12="","",N($F12)*N($G12)+N($H12)) | P12: =IF(OR($B12="",$E12=""),"",IF($J12<>"",$J12,TODAY())-$E12) | Q12: =IF(OR($B12="",$I12="",$I12="En cartera"),"",($K12-$G12)*$F12-N($H12)-N($L12)) | R12: =IF(OR($B12="",$I12<>"En cartera",$M12=""),"",($M12-$G12)*$F12-N($H12)) | S12: =IF($B12="","",SUMIFS(Dividendos!$I$2:$I$301,Dividendos!$C$2:$C$301,$A12)) | T12: =IF($B12="","",SUMIFS(Operaciones!$AE$2:$AE$1001,Operaciones!$R$2:$R$1001,$A12)) | U12: =IF($B12="","",N($Q12)+$S12+$T12) | V12: =IF(OR($B12="",N($F12)=0),"",(N($F12)*N($G12)-$S12-$T12)/$F12) | W12: =IF(OR($B12="",N($F12)*N($G12)=0),"",$U12/($F12*$G12)) | X12: =IF(OR($W12="",$P12=""),"",$W12*365/MAX($P12,1)) | Y12: =IF($B12="","",IF(OR($A12="",$E12="",$F12="",$G12="",$I12=""),"Faltan datos obligatorios",IF(COUNTIF($A$2:$A$201,$A12)>1,"ID lote duplicado",IF(AND($I12<>"En cartera",OR($J12="",$K12="")),"Falta fecha o precio de salida",IF(AND($J12<>"",$J12<$E12),"Salida anterior a entrada",IF(AND($I12="En cartera",$M12=""),"OK (sin precio actual)","OK"))))))
O13: =IF($B13="","",N($F13)*N($G13)+N($H13)) | P13: =IF(OR($B13="",$E13=""),"",IF($J13<>"",$J13,TODAY())-$E13) | Q13: =IF(OR($B13="",$I13="",$I13="En cartera"),"",($K13-$G13)*$F13-N($H13)-N($L13)) | R13: =IF(OR($B13="",$I13<>"En cartera",$M13=""),"",($M13-$G13)*$F13-N($H13)) | S13: =IF($B13="","",SUMIFS(Dividendos!$I$2:$I$301,Dividendos!$C$2:$C$301,$A13)) | T13: =IF($B13="","",SUMIFS(Operaciones!$AE$2:$AE$1001,Operaciones!$R$2:$R$1001,$A13)) | U13: =IF($B13="","",N($Q13)+$S13+$T13) | V13: =IF(OR($B13="",N($F13)=0),"",(N($F13)*N($G13)-$S13-$T13)/$F13) | W13: =IF(OR($B13="",N($F13)*N($G13)=0),"",$U13/($F13*$G13)) | X13: =IF(OR($W13="",$P13=""),"",$W13*365/MAX($P13,1)) | Y13: =IF($B13="","",IF(OR($A13="",$E13="",$F13="",$G13="",$I13=""),"Faltan datos obligatorios",IF(COUNTIF($A$2:$A$201,$A13)>1,"ID lote duplicado",IF(AND($I13<>"En cartera",OR($J13="",$K13="")),"Falta fecha o precio de salida",IF(AND($J13<>"",$J13<$E13),"Salida anterior a entrada",IF(AND($I13="En cartera",$M13=""),"OK (sin precio actual)","OK"))))))
O14: =IF($B14="","",N($F14)*N($G14)+N($H14)) | P14: =IF(OR($B14="",$E14=""),"",IF($J14<>"",$J14,TODAY())-$E14) | Q14: =IF(OR($B14="",$I14="",$I14="En cartera"),"",($K14-$G14)*$F14-N($H14)-N($L14)) | R14: =IF(OR($B14="",$I14<>"En cartera",$M14=""),"",($M14-$G14)*$F14-N($H14)) | S14: =IF($B14="","",SUMIFS(Dividendos!$I$2:$I$301,Dividendos!$C$2:$C$301,$A14)) | T14: =IF($B14="","",SUMIFS(Operaciones!$AE$2:$AE$1001,Operaciones!$R$2:$R$1001,$A14)) | U14: =IF($B14="","",N($Q14)+$S14+$T14) | V14: =IF(OR($B14="",N($F14)=0),"",(N($F14)*N($G14)-$S14-$T14)/$F14) | W14: =IF(OR($B14="",N($F14)*N($G14)=0),"",$U14/($F14*$G14)) | X14: =IF(OR($W14="",$P14=""),"",$W14*365/MAX($P14,1)) | Y14: =IF($B14="","",IF(OR($A14="",$E14="",$F14="",$G14="",$I14=""),"Faltan datos obligatorios",IF(COUNTIF($A$2:$A$201,$A14)>1,"ID lote duplicado",IF(AND($I14<>"En cartera",OR($J14="",$K14="")),"Falta fecha o precio de salida",IF(AND($J14<>"",$J14<$E14),"Salida anterior a entrada",IF(AND($I14="En cartera",$M14=""),"OK (sin precio actual)","OK"))))))
... O201: =IF($B201="","",N($F201)*N($G201)+N($H201)) | P201: =IF(OR($B201="",$E201=""),"",IF($J201<>"",$J201,TODAY())-$E201) | Q201: =IF(OR($B201="",$I201="",$I201="En cartera"),"",($K201-$G201)*$F201-N($H201)-N($L201)) | R201: =IF(OR($B201="",$I201<>"En cartera",$M201=""),"",($M201-$G201)*$F201-N($H201)) | S201: =IF($B201="","",SUMIFS(Dividendos!$I$2:$I$301,Dividendos!$C$2:$C$301,$A201)) | T201: =IF($B201="","",SUMIFS(Operaciones!$AE$2:$AE$1001,Operaciones!$R$2:$R$1001,$A201)) | U201: =IF($B201="","",N($Q201)+$S201+$T201) | V201: =IF(OR($B201="",N($F201)=0),"",(N($F201)*N($G201)-$S201-$T201)/$F201) | W201: =IF(OR($B201="",N($F201)*N($G201)=0),"",$U201/($F201*$G201)) | X201: =IF(OR($W201="",$P201=""),"",$W201*365/MAX($P201,1)) | Y201: =IF($B201="","",IF(OR($A201="",$E201="",$F201="",$G201="",$I201=""),"Faltan datos obligatorios",IF(COUNTIF($A$2:$A$201,$A201)>1,"ID lote duplicado",IF(AND($I201<>"En cartera",OR($J201="",$K201="")),"Falta fecha o precio de salida",IF(AND($J201<>"",$J201<$E201),"Salida anterior a entrada",IF(AND($I201="En cartera",$M201=""),"OK (sin precio actual)","OK"))))))

Sheet Dividendos
A1: Fecha cobro | B1: Activo | C1: ID lote | D1: Nº acciones | E1: Dividendo por acción | F1: Retención $ | G1: Notas | H1: Bruto $ | I1: Neto $ | J1: Control
A2: 46296 | B2: KO | C2: L1 | D2: 100 | E2: 0.51 | F2: 7.65 | G2: EJEMPLO · borrar esta fila | H2: =IF($B2="","",N($D2)*N($E2)) -> 51 | I2: =IF($B2="","",$H2-N($F2)) -> 43.35 | J2: =IF($B2="","",IF(OR($A2="",$D2="",$E2=""),"Faltan datos obligatorios",IF(AND($C2<>"",ISNA(MATCH($C2,Acciones!$A$2:$A$201,0))),"El ID lote no existe en Acciones","OK"))) -> OK
H3: =IF($B3="","",N($D3)*N($E3)) | I3: =IF($B3="","",$H3-N($F3)) | J3: =IF($B3="","",IF(OR($A3="",$D3="",$E3=""),"Faltan datos obligatorios",IF(AND($C3<>"",ISNA(MATCH($C3,Acciones!$A$2:$A$201,0))),"El ID lote no existe en Acciones","OK")))
H4: =IF($B4="","",N($D4)*N($E4)) | I4: =IF($B4="","",$H4-N($F4)) | J4: =IF($B4="","",IF(OR($A4="",$D4="",$E4=""),"Faltan datos obligatorios",IF(AND($C4<>"",ISNA(MATCH($C4,Acciones!$A$2:$A$201,0))),"El ID lote no existe en Acciones","OK")))
H5: =IF($B5="","",N($D5)*N($E5)) | I5: =IF($B5="","",$H5-N($F5)) | J5: =IF($B5="","",IF(OR($A5="",$D5="",$E5=""),"Faltan datos obligatorios",IF(AND($C5<>"",ISNA(MATCH($C5,Acciones!$A$2:$A$201,0))),"El ID lote no existe en Acciones","OK")))
H6: =IF($B6="","",N($D6)*N($E6)) | I6: =IF($B6="","",$H6-N($F6)) | J6: =IF($B6="","",IF(OR($A6="",$D6="",$E6=""),"Faltan datos obligatorios",IF(AND($C6<>"",ISNA(MATCH($C6,Acciones!$A$2:$A$201,0))),"El ID lote no existe en Acciones","OK")))
